Workbook
Name Slicer_Category: #N/A
Name Slicer_Region: #N/A

Sheet Sales Dashboard
A3: Sum of Sales
A4: 34765938 | D4: Count of Order ID | E4: unique order
D5: 500 | E5: =IF(COUNTIF($A$2:A2,A2)=1,1,0) -> 0 | G5: Order_Date | H5: Sum of Sales
G6: \ | H6: 1785
G7: 13/01/2025 | H7: 574930
G8: 13/01/2026 | H8: 275000
G9: 13/02/2025 | H9: 100
A10: Average Sales per Order | G10: 13/02/2026 | H10: 12080
A11: =IFERROR(A4/D5,0) -> 69531.875 | G11: 13/03/2025 | H11: 180000
G12: 13/03/2026 | H12: 305589.5
G13: 13/04/2025 | H13: 143760 | O13: Category | P13: Sum of Sales
G14: 13/05/2025 | H14: 15360 | O14: Home Appliances | P14: 7000575
G15: 13/05/2026 | H15: 69325 | O15: Grand Total | P15: 7000575
G16: 13/08/2025 | H16: 18780
A17: Region | B17: Sum of Sales | G17: 13/10/2025 | H17: 142408.25
A18: East | B18: 4041922 | G18: 13/12/2025 | H18: 21710
A19: Grand Total | B19: 4041922 | G19: 14/01/2026 | H19: 79800
G20: 14/02/2026 | H20: 1062
G21: 14/03/2025 | H21: 650.25
G22: 14/03/2026 | H22: 140
G23: 14/05/2025 | H23: 68
G24: 14/06/2025 | H24: 12320
G25: 14/07/2025 | H25: 28160
G26: 14/12/2025 | H26: 198900
G27: 15/01/2025 | H27: 20505
G28: 15/03/2026 | H28: 14820
G29: 15/04/2026 | H29: 59850
G30: 15/05/2025 | H30: 43732.5
G31: 15/06/2025 | H31: 10127
... G202: 31/12/2025 | H202: 224
G203: 45658 | H203: 15012.5
G204: 45659 | H204: 53200
G205: 45660 | H205: 10410
G206: 45661 | H206: 17050
G207: 45664 | H207: 132000
G208: 45665 | H208: 110000
G209: 45666 | H209: 441009.5
G210: 45667 | H210: 61251
G211: 45668 | H211: 3150
G212: 45669 | H212: 149985
...

Sheet Sheet1
A1: Order ID | B1: Customer_ID | C1: Product_ID | D1: Order_Date | E1: Delivery_Date | F1: Customer_Name | G1: Gender | H1: DOB | I1: City | J1: Region | K1: Category | L1: Product_Name | M1: Quantity | N1: Unit_Price | O1: Discount_% | P1: Sales | Q1: Rating | R1: Payment_Mode | S1: Salesperson | T1: Email | U1: Phone | V1: Order_Status | W1: Customer Classification | X1: Standarized Customer Name | Y1: Customer Code | Z1: Standerized Email | AA1: Customer age | AB1: Delivery Time | AC1: DELIVERY status
A2: ORD10001 | B2: C010 | C2: P101 | D2: 45725 | E2: 14/09/2025 | F2: pooja shah | G2: Female | H2: 16/09/1994 | I2: Bengaluru | J2: South | K2: Electronics | L2: Laptop | M2: 5 | N2: 55000 | O2: 5 | P2: 261250 | Q2: 3 | R2: NetBanking | S2: Aisha | T2: pooja.shah@company.com | U2: 9380975626 | V2: Pending | W2: =IF(OR(Q2<=2,V2="Cancelled"),"Blacklisted",IF(AND(P2>100000,Q2>=4,O2<=10%,V2="Completed"),"Platinum",IF(AND(P2>=50000,Q2>=3,V2="Completed"),"Gold",IF(AND(P2<50000,V2="Completed"),"Silver","")))) | X2: =PROPER(TRIM(F2)) -> Pooja Shah | Y2: =LEFT(F2,3)&MID(B2,2,3)&LEFT(I2,2) -> poo010Be | Z2: =IF(ISNUMBER(SEARCH("@",T2)),LOWER(TRIM(T2)),"invalid email") -> pooja.shah@company.com | AA2: =IF(H4="","",IFERROR(DATEDIF(IF(ISNUMBER(H4),H4,DATE(VALUE(RIGHT(H4,4)),VALUE(MID(H4,3,2)),VALUE(LEFT(H4,2)))),TODAY(),"Y"),"")) | AB2: =IF(OR(D2="",E2=""),"",IFERROR(DATE(MID(E2,7,4),MID(E2,4,2),LEFT(E2,2))-DATE(MID(D2,7,4),MID(D2,4,2),LEFT(D2,2)),"")) | AC2: =IF(E2="","Pending",IF(AB2<=5,"On time","Delayed")) -> Delayed
A3: ORD10001 | B3: C008 | C3: P202 | D3: 18/09/2025 | E3: 22/09/2025 | F3: Kavya Nair | G3: Female | H3: 27767 | I3: Hyderabad | J3: South | K3: Home Appliances | L3: Iron | M3: 4 | N3: 2200 | O3: 10 | P3: 7920 | Q3: 4 | R3: Cash | S3: Ritika | T3: KAvya.nair@company.com | U3: 9431429797 | V3: Completed | W3: =IF(OR(Q3<=2,V3="Cancelled"),"Blacklisted",IF(AND(P3>100000,Q3>=4,O3<=10%,V3="Completed"),"Platinum",IF(AND(P3>=50000,Q3>=3,V3="Completed"),"Gold",IF(AND(P3<50000,V3="Completed"),"Silver","")))) -> Silver | X3: =PROPER(TRIM(F3)) -> Kavya Nair | Y3: =LEFT(F3,3)&MID(B3,2,3)&LEFT(I3,2) -> Kav008Hy | Z3: =IF(ISNUMBER(SEARCH("@",T3)),LOWER(TRIM(T3)),"invalid email") -> kavya.nair@company.com | AA3: =DATEDIF(H3,TODAY(),"Y") -> 50 | AB3: =IF(OR(D3="",E3=""),"",IFERROR(DATE(MID(E3,7,4),MID(E3,4,2),LEFT(E3,2))-DATE(MID(D3,7,4),MID(D3,4,2),LEFT(D3,2)),"")) -> 4 | AC3: =IF(E3="","Pending",IF(AB3<=5,"On time","Delayed")) -> On time
A4: ORD10001 | B4: C008 | C4: P104 | D4: 27/04/2025 | E4: 45752 | F4: Kavya Nair | G4: Female | H4: 16/10/2000 | I4: Delhi | J4: North | K4: Electronics | L4: Monitor | M4: 17 | N4: 12000 | O4: 10 | P4: 183600 | Q4: 1 | R4: NetBanking | S4: Rahul | T4: kavya.nair@company.com | U4: 9129865339 | V4: Completed | W4: =IF(OR(Q4<=2,V4="Cancelled"),"Blacklisted",IF(AND(P4>100000,Q4>=4,O4<=10%,V4="Completed"),"Platinum",IF(AND(P4>=50000,Q4>=3,V4="Completed"),"Gold",IF(AND(P4<50000,V4="Completed"),"Silver","")))) -> Blacklisted | X4: =PROPER(TRIM(F4)) -> Kavya Nair | Y4: =LEFT(F4,3)&MID(B4,2,3)&LEFT(I4,2) -> Kav008De | Z4: =IF(ISNUMBER(SEARCH("@",T4)),LOWER(TRIM(T4)),"invalid email") -> kavya.nair@company.com | AA4: =IF(H3="","",IFERROR(DATEDIF(IF(ISNUMBER(H3),H3,DATE(VALUE(RIGHT(H3,4)),VALUE(MID(H3,3,2)),VALUE(LEFT(H3,2)))),TODAY(),"Y"),"")) -> 50 | AB4: =IF(OR(D4="",E4=""),"",IFERROR(DATE(MID(E4,7,4),MID(E4,4,2),LEFT(E4,2))-DATE(MID(D4,7,4),MID(D4,4,2),LEFT(D4,2)),"")) | AC4: =IF(E4="","Pending",IF(AB4<=5,"On time","Delayed")) -> Delayed
A5: ORD10001 | B5: C008 | C5: P202 | D5: 21/03/2026 | E5: 46057 | F5: Kavya Nair | G5: Female | H5: 38171 | I5: Bengaluru | J5: South | K5: Home Appliances | L5: Iron | M5: 5 | N5: 2200 | O5: 5 | P5: 10450 | Q5: 5 | R5: NetBanking | S5: Aisha | T5: kavya.nair@company.com | U5: 9600261125 | V5: Cancelled | W5: =IF(OR(Q5<=2,V5="Cancelled"),"Blacklisted",IF(AND(P5>100000,Q5>=4,O5<=10%,V5="Completed"),"Platinum",IF(AND(P5>=50000,Q5>=3,V5="Completed"),"Gold",IF(AND(P5<50000,V5="Completed"),"Silver","")))) -> Blacklisted | X5: =PROPER(TRIM(F5)) -> Kavya Nair | Y5: =LEFT(F5,3)&MID(B5,2,3)&LEFT(I5,2) -> Kav008Be | Z5: =IF(ISNUMBER(SEARCH("@",T5)),LOWER(TRIM(T5)),"invalid email") -> kavya.nair@company.com | AA5: =IF(H2="","",IFERROR(DATEDIF(IF(ISNUMBER(H2),H2,DATE(VALUE(RIGHT(H2,4)),VALUE(MID(H2,3,2)),VALUE(LEFT(H2,2)))),TODAY(),"Y"),"")) | AB5: =IF(OR(D5="",E5=""),"",IFERROR(DATE(MID(E5,7,4),MID(E5,4,2),LEFT(E5,2))-DATE(MID(D5,7,4),MID(D5,4,2),LEFT(D5,2)),"")) | AC5: =IF(E5="","Pending",IF(AB5<=5,"On time","Delayed")) -> Delayed
A6: ORD10001 | B6: C009 | C6: P103 | D6: 27/09/2025 | E6: 45848 | F6: Mohit Verma | G6: Male | H6: 13/04/1976 | I6: Delhi | J6: North | K6: Electronics | L6: Keyboard | M6: 8 | N6: 1200 | O6: 5 | P6: 9120 | Q6: 2 | R6: Card | S6: Aisha | T6: mohit.verma@company.com | U6: 9724635978 | V6: Pending | W6: =IF(OR(Q6<=2,V6="Cancelled"),"Blacklisted",IF(AND(P6>100000,Q6>=4,O6<=10%,V6="Completed"),"Platinum",IF(AND(P6>=50000,Q6>=3,V6="Completed"),"Gold",IF(AND(P6<50000,V6="Completed"),"Silver","")))) -> Blacklisted | X6: =PROPER(TRIM(F6)) -> Mohit Verma | Y6: =LEFT(F6,3)&MID(B6,2,3)&LEFT(I6,2) -> Moh009De | Z6: =IF(ISNUMBER(SEARCH("@",T6)),LOWER(TRIM(T6)),"invalid email") -> mohit.verma@company.com | AA6: =IF(H5="","",IFERROR(DATEDIF(IF(ISNUMBER(H5),H5,DATE(VALUE(RIGHT(H5,4)),VALUE(MID(H5,3,2)),VALUE(LEFT(H5,2)))),TODAY(),"Y"),"")) -> 22 | AB6: =IF(OR(D6="",E6=""),"",IFERROR(DATE(MID(E6,7,4),MID(E6,4,2),LEFT(E6,2))-DATE(MID(D6,7,4),MID(D6,4,2),LEFT(D6,2)),"")) | AC6: =IF(E6="","Pending",IF(AB6<=5,"On time","Delayed")) -> Delayed
A7: ORD10006 | B7: C007 | C7: P202 | D7: 46113 | E7: 46357 | F7: arjun Rao | G7: Male | H7: 32326 | I7: Hyderabad | J7: South | K7: Home Appliances | L7: Iron | M7: 4 | N7: 2200 | O7: 0 | P7: 8800 | Q7: 1 | R7: UPI | S7: Ritika | T7: arjun.rao@company.com | U7: 9780584905 | V7: Completed | W7: =IF(OR(Q7<=2,V7="Cancelled"),"Blacklisted",IF(AND(P7>100000,Q7>=4,O7<=10%,V7="Completed"),"Platinum",IF(AND(P7>=50000,Q7>=3,V7="Completed"),"Gold",IF(AND(P7<50000,V7="Completed"),"Silver","")))) -> Blacklisted | X7: =PROPER(TRIM(F7)) -> Arjun Rao | Y7: =LEFT(F7,3)&MID(B7,2,3)&LEFT(I7,2) -> arj007Hy | Z7: =IF(ISNUMBER(SEARCH("@",T7)),LOWER(TRIM(T7)),"invalid email") -> arjun.rao@company.com | AA7: =IF(H6="","",IFERROR(DATEDIF(IF(ISNUMBER(H6),H6,DATE(VALUE(RIGHT(H6,4)),VALUE(MID(H6,3,2)),VALUE(LEFT(H6,2)))),TODAY(),"Y"),"")) | AB7: =IF(OR(D7="",E7=""),"",IFERROR(DATE(MID(E7,7,4),MID(E7,4,2),LEFT(E7,2))-DATE(MID(D7,7,4),MID(D7,4,2),LEFT(D7,2)),"")) | AC7: =IF(E7="","Pending",IF(AB7<=5,"On time","Delayed")) -> Delayed
A8: ORD10007 | B8: C008 | C8: P201 | D8: 31/02/2025 | E8: 25/02/2026 | F8: Kavya Nair | G8: Female | H8: 20/03/2003 | I8: Hyderabad | J8: South | K8: Home Appliances | L8: Mixer | M8: 2 | N8: 3500 | O8: 5 | P8: 6650 | Q8: 1 | R8: UPI | S8: Ritika | T8: kavya.nair@company.com | U8: 9958252176 | V8: Completed | W8: =IF(OR(Q8<=2,V8="Cancelled"),"Blacklisted",IF(AND(P8>100000,Q8>=4,O8<=10%,V8="Completed"),"Platinum",IF(AND(P8>=50000,Q8>=3,V8="Completed"),"Gold",IF(AND(P8<50000,V8="Completed"),"Silver","")))) -> Blacklisted | X8: =PROPER(TRIM(F8)) -> Kavya Nair | Y8: =LEFT(F8,3)&MID(B8,2,3)&LEFT(I8,2) -> Kav008Hy | Z8: =IF(ISNUMBER(SEARCH("@",T8)),LOWER(TRIM(T8)),"invalid email") -> kavya.nair@company.com | AA8: =IF(H7="","",IFERROR(DATEDIF(IF(ISNUMBER(H7),H7,DATE(VALUE(RIGHT(H7,4)),VALUE(MID(H7,3,2)),VALUE(LEFT(H7,2)))),TODAY(),"Y"),"")) -> 38 | AB8: =IF(OR(D8="",E8=""),"",IFERROR(DATE(MID(E8,7,4),MID(E8,4,2),LEFT(E8,2))-DATE(MID(D8,7,4),MID(D8,4,2),LEFT(D8,2)),"")) -> 359 | AC8: =IF(E8="","Pending",IF(AB8<=5,"On time","Delayed")) -> Delayed
A9: ORD10008 | B9: C002 | C9: P104 | D9: 13/04/2025 | E9: 19/04/2025 | F9: Priya Patel | G9: Female | H9: 34883 | I9: Mumbai | J9: West | K9: Home Appliances | L9: Monitor | M9: 14 | N9: 12000 | O9: 15 | P9: 142800 | Q9: 4 | R9: NetBanking | S9: Ritika | T9: priYa.patel@company.com | U9: 9705521654 | V9: Completed | W9: =IF(OR(Q9<=2,V9="Cancelled"),"Blacklisted",IF(AND(P9>100000,Q9>=4,O9<=10%,V9="Completed"),"Platinum",IF(AND(P9>=50000,Q9>=3,V9="Completed"),"Gold",IF(AND(P9<50000,V9="Completed"),"Silver","")))) -> Gold | X9: =PROPER(TRIM(F9)) -> Priya Patel | Y9: =LEFT(F9,3)&MID(B9,2,3)&LEFT(I9,2) -> Pri002Mu | Z9: =IF(ISNUMBER(SEARCH("@",T9)),LOWER(TRIM(T9)),"invalid email") -> priya.patel@company.com | AA9: =IF(H8="","",IFERROR(DATEDIF(IF(ISNUMBER(H8),H8,DATE(VALUE(RIGHT(H8,4)),VALUE(MID(H8,3,2)),VALUE(LEFT(H8,2)))),TODAY(),"Y"),"")) | AB9: =IF(OR(D9="",E9=""),"",IFERROR(DATE(MID(E9,7,4),MID(E9,4,2),LEFT(E9,2))-DATE(MID(D9,7,4),MID(D9,4,2),LEFT(D9,2)),"")) -> 6 | AC9: =IF(E9="","Pending",IF(AB9<=5,"On time","Delayed")) -> Delayed
A10: ORD10009 | B10: C008 | C10: P104 | D10: 31/01/2026 | E10: 46055 | F10: kavya Nair | G10: Female | H10: 35585 | I10: Pune | J10: West | K10: Home Appliances | L10: Monitor | M10: 4 | N10: 12000 | O10: 15 | P10: 40800 | Q10: 4 | R10: UPI | S10: Neha | T10: kavya.nair@company.com | U10: 9588041011 | V10: Completed | W10: =IF(OR(Q10<=2,V10="Cancelled"),"Blacklisted",IF(AND(P10>100000,Q10>=4,O10<=10%,V10="Completed"),"Platinum",IF(AND(P10>=50000,Q10>=3,V10="Completed"),"Gold",IF(AND(P10<50000,V10="Completed"),"Silver","")))) -> Silver | X10: =PROPER(TRIM(F10)) -> Kavya Nair | Y10: =LEFT(F10,3)&MID(B10,2,3)&LEFT(I10,2) -> kav008Pu | Z10: =IF(ISNUMBER(SEARCH("@",T10)),LOWER(TRIM(T10)),"invalid email") -> kavya.nair@company.com | AA10: =IF(H9="","",IFERROR(DATEDIF(IF(ISNUMBER(H9),H9,DATE(VALUE(RIGHT(H9,4)),VALUE(MID(H9,3,2)),VALUE(LEFT(H9,2)))),TODAY(),"Y"),"")) -> 31 | AB10: =IF(OR(D10="",E10=""),"",IFERROR(DATE(MID(E10,7,4),MID(E10,4,2),LEFT(E10,2))-DATE(MID(D10,7,4),MID(D10,4,2),LEFT(D10,2)),"")) | AC10: =IF(E10="","Pending",IF(AB10<=5,"On time","Delayed")) -> Delayed
A11: ORD10010 | B11: C002 | C11: P301 | D11: 25/03/2025 | E11: 27/03/2025 | F11: Priya Patel | G11: Female | H11: 33055 | I11: Mumbai | J11: West | K11: Stationery | L11: Notebook | M11: 6 | N11: 60 | O11: 0 | P11: 360 | Q11: 4 | R11: Card | S11: Neha | T11: PRiya.patel@company.com | U11: 9340540608 | V11: Completed | W11: =IF(OR(Q11<=2,V11="Cancelled"),"Blacklisted",IF(AND(P11>100000,Q11>=4,O11<=10%,V11="Completed"),"Platinum",IF(AND(P11>=50000,Q11>=3,V11="Completed"),"Gold",IF(AND(P11<50000,V11="Completed"),"Silver","")))) -> Silver | X11: =PROPER(TRIM(F11)) -> Priya Patel | Y11: =LEFT(F11,3)&MID(B11,2,3)&LEFT(I11,2) -> Pri002Mu | Z11: =IF(ISNUMBER(SEARCH("@",T11)),LOWER(TRIM(T11)),"invalid email") -> priya.patel@company.com | AA11: =IF(H10="","",IFERROR(DATEDIF(IF(ISNUMBER(H10),H10,DATE(VALUE(RIGHT(H10,4)),VALUE(MID(H10,3,2)),VALUE(LEFT(H10,2)))),TODAY(),"Y"),"")) -> 29 | AB11: =IF(OR(D11="",E11=""),"",IFERROR(DATE(MID(E11,7,4),MID(E11,4,2),LEFT(E11,2))-DATE(MID(D11,7,4),MID(D11,4,2),LEFT(D11,2)),"")) -> 2 | AC11: =IF(E11="","Pending",IF(AB11<=5,"On time","Delayed")) -> On time
A12: ORD10011 | B12: C003 | C12: P202 | D12: 19/09/2025 | E12: 23/09/2025 | F12: Rohit Singh | G12: Male | H12: 30229 | I12: Delhi | J12: North | K12: Home Appliances | L12: Iron | M12: -3 | N12: 2200 | O12: 0 | P12: 35200 | Q12: 2 | R12: Card | S12: Rahul | T12: rohit.singh@company.com | U12: 9521710321 | V12: Pending | W12: =IF(OR(Q12<=2,V12="Cancelled"),"Blacklisted",IF(AND(P12>100000,Q12>=4,O12<=10%,V12="Completed"),"Platinum",IF(AND(P12>=50000,Q12>=3,V12="Completed"),"Gold",IF(AND(P12<50000,V12="Completed"),"Silver","")))) -> Blacklisted | X12: =PROPER(TRIM(F12)) -> Rohit Singh | Y12: =LEFT(F12,3)&MID(B12,2,3)&LEFT(I12,2) -> Roh003De | Z12: =IF(ISNUMBER(SEARCH("@",T12)),LOWER(TRIM(T12)),"invalid email") -> rohit.singh@company.com | AA12: =IF(H11="","",IFERROR(DATEDIF(IF(ISNUMBER(H11),H11,DATE(VALUE(RIGHT(H11,4)),VALUE(MID(H11,3,2)),VALUE(LEFT(H11,2)))),TODAY(),"Y"),"")) -> 36 | AB12: =IF(OR(D12="",E12=""),"",IFERROR(DATE(MID(E12,7,4),MID(E12,4,2),LEFT(E12,2))-DATE(MID(D12,7,4),MID(D12,4,2),LEFT(D12,2)),"")) -> 4 | AC12: =IF(E12="","Pending",IF(AB12<=5,"On time","Delayed")) -> On time
A13: ORD10012 | B13: C008 | C13: P201 | D13: 45872 | E13: 15/03/2025 | F13: Kavya Nair | G13: Female | H13: 23/01/1982 | I13: Ahmedabad | J13: West | K13: Home Appliances | L13: Mixer | M13: 10 | N13: 3500 | O13: 5 | P13: 33250 | Q13: 5 | R13: Card | S13: Aisha | T13: kavya.nair@company.com | U13: 9123535241 | V13: Cancelled | W13: =IF(OR(Q13<=2,V13="Cancelled"),"Blacklisted",IF(AND(P13>100000,Q13>=4,O13<=10%,V13="Completed"),"Platinum",IF(AND(P13>=50000,Q13>=3,V13="Completed"),"Gold",IF(AND(P13<50000,V13="Completed"),"Silver","")))) -> Blacklisted | X13: =PROPER(TRIM(F13)) -> Kavya Nair | Y13: =LEFT(F13,3)&MID(B13,2,3)&LEFT(I13,2) -> Kav008Ah | Z13: =IF(ISNUMBER(SEARCH("@",T13)),LOWER(TRIM(T13)),"invalid email") -> kavya.nair@company.com | AA13: =IF(H12="","",IFERROR(DATEDIF(IF(ISNUMBER(H12),H12,DATE(VALUE(RIGHT(H12,4)),VALUE(MID(H12,3,2)),VALUE(LEFT(H12,2)))),TODAY(),"Y"),"")) -> 44 | AB13: =IF(OR(D13="",E13=""),"",IFERROR(DATE(MID(E13,7,4),MID(E13,4,2),LEFT(E13,2))-DATE(MID(D13,7,4),MID(D13,4,2),LEFT(D13,2)),"")) | AC13: =IF(E13="","Pending",IF(AB13<=5,"On time","Delayed")) -> Delayed
A14: ORD10013 | B14: C002 | C14: P202 | D14: 45931 | E14: 15/01/2025 | F14: Priya Patel | G14: Female | H14: 33762 | I14: Pune | J14: West | K14: Home Appliances | L14: Iron | M14: 15 | N14: 2200 | O14: 10 | P14: 29700 | Q14: 1 | R14: UPI | S14: Neha | T14: priya.patel@company.com | U14: 9367316892 | V14: Pending | W14: =IF(OR(Q14<=2,V14="Cancelled"),"Blacklisted",IF(AND(P14>100000,Q14>=4,O14<=10%,V14="Completed"),"Platinum",IF(AND(P14>=50000,Q14>=3,V14="Completed"),"Gold",IF(AND(P14<50000,V14="Completed"),"Silver","")))) -> Blacklisted | X14: =PROPER(TRIM(F14)) -> Priya Patel | Y14: =LEFT(F14,3)&MID(B14,2,3)&LEFT(I14,2) -> Pri002Pu | Z14: =IF(ISNUMBER(SEARCH("@",T14)),LOWER(TRIM(T14)),"invalid email") -> priya.patel@company.com | AA14: =IF(H13="","",IFERROR(DATEDIF(IF(ISNUMBER(H13),H13,DATE(VALUE(RIGHT(H13,4)),VALUE(MID(H13,3,2)),VALUE(LEFT(H13,2)))),TODAY(),"Y"),"")) | AB14: =IF(OR(D14="",E14=""),"",IFERROR(DATE(MID(E14,7,4),MID(E14,4,2),LEFT(E14,2))-DATE(MID(D14,7,4),MID(D14,4,2),LEFT(D14,2)),"")) | AC14: =IF(E14="","Pending",IF(AB14<=5,"On time","Delayed")) -> Delayed
A15: ORD10014 | B15: C003 | C15: P202 | D15: 45903 | E15: 13/03/2025 | F15: rohit Singh | G15: Male | H15: 19/03/2002 | I15: Mumbai | J15: West | K15: Home Appliances | L15: Iron | M15: 17 | N15: 2200 | O15: 5 | P15: 35530 | Q15: 1 | R15: Cash | S15: Karan | T15: rOhit.singh@company.com | U15: 9778489803 | V15: Completed | W15: =IF(OR(Q15<=2,V15="Cancelled"),"Blacklisted",IF(AND(P15>100000,Q15>=4,O15<=10%,V15="Completed"),"Platinum",IF(AND(P15>=50000,Q15>=3,V15="Completed"),"Gold",IF(AND(P15<50000,V15="Completed"),"Silver","")))) -> Blacklisted | X15: =PROPER(TRIM(F15)) -> Rohit Singh | Y15: =LEFT(F15,3)&MID(B15,2,3)&LEFT(I15,2) -> roh003Mu | Z15: =IF(ISNUMBER(SEARCH("@",T15)),LOWER(TRIM(T15)),"invalid email") -> rohit.singh@company.com | AA15: =IF(H14="","",IFERROR(DATEDIF(IF(ISNUMBER(H14),H14,DATE(VALUE(RIGHT(H14,4)),VALUE(MID(H14,3,2)),VALUE(LEFT(H14,2)))),TODAY(),"Y"),"")) -> 34 | AB15: =IF(OR(D15="",E15=""),"",IFERROR(DATE(MID(E15,7,4),MID(E15,4,2),LEFT(E15,2))-DATE(MID(D15,7,4),MID(D15,4,2),LEFT(D15,2)),"")) | AC15: =IF(E15="","Pending",IF(AB15<=5,"On time","Delayed")) -> Delayed
A16: ORD10015 | B16: C008 | C16: P201 | D16: 26/07/2025 | E16: 45846 | F16: Kavya nair | G16: Female | H16: 17/01/2001 | I16: Mumbai | J16: West | K16: Home Appliances | L16: Mixer | M16: 15 | N16: 3500 | O16: 15 | P16: 44625 | Q16: 2 | R16: Cash | S16: Neha | T16: kavya.nair@company.com | U16: 9582960180 | V16: Cancelled | W16: =IF(OR(Q16<=2,V16="Cancelled"),"Blacklisted",IF(AND(P16>100000,Q16>=4,O16<=10%,V16="Completed"),"Platinum",IF(AND(P16>=50000,Q16>=3,V16="Completed"),"Gold",IF(AND(P16<50000,V16="Completed"),"Silver","")))) -> Blacklisted | X16: =PROPER(TRIM(F16)) -> Kavya Nair | Y16: =LEFT(F16,3)&MID(B16,2,3)&LEFT(I16,2) -> Kav008Mu | Z16: =IF(ISNUMBER(SEARCH("@",T16)),LOWER(TRIM(T16)),"invalid email") -> kavya.nair@company.com | AA16: =IF(H15="","",IFERROR(DATEDIF(IF(ISNUMBER(H15),H15,DATE(VALUE(RIGHT(H15,4)),VALUE(MID(H15,3,2)),VALUE(LEFT(H15,2)))),TODAY(),"Y"),"")) | AB16: =IF(OR(D16="",E16=""),"",IFERROR(DATE(MID(E16,7,4),MID(E16,4,2),LEFT(E16,2))-DATE(MID(D16,7,4),MID(D16,4,2),LEFT(D16,2)),"")) | AC16: =IF(E16="","Pending",IF(AB16<=5,"On time","Delayed")) -> Delayed
A17: ORD10016 | B17: C010 | C17: P103 | D17: 46238 | E17: 46330 | F17: Pooja Shah | G17: Female | H17: 37564 | I17: Hyderabad | J17: South | K17: Electronics | L17: Keyboard | M17: 3 | N17: 1200 | O17: 5 | P17: 3420 | Q17: 5 | R17: UPI | S17: Ritika | T17: pooja.shahcompany.com | U17: 9611394005 | V17: Completed | W17: =IF(OR(Q17<=2,V17="Cancelled"),"Blacklisted",IF(AND(P17>100000,Q17>=4,O17<=10%,V17="Completed"),"Platinum",IF(AND(P17>=50000,Q17>=3,V17="Completed"),"Gold",IF(AND(P17<50000,V17="Completed"),"Silver","")))) -> Silver | X17: =PROPER(TRIM(F17)) -> Pooja Shah | Y17: =LEFT(F17,3)&MID(B17,2,3)&LEFT(I17,2) -> Poo010Hy | Z17: =IF(ISNUMBER(SEARCH("@",T17)),LOWER(TRIM(T17)),"invalid email") -> invalid email | AA17: =IF(H16="","",IFERROR(DATEDIF(IF(ISNUMBER(H16),H16,DATE(VALUE(RIGHT(H16,4)),VALUE(MID(H16,3,2)),VALUE(LEFT(H16,2)))),TODAY(),"Y"),"")) | AB17: =IF(OR(D17="",E17=""),"",IFERROR(DATE(MID(E17,7,4),MID(E17,4,2),LEFT(E17,2))-DATE(MID(D17,7,4),MID(D17,4,2),LEFT(D17,2)),"")) | AC17: =IF(E17="","Pending",IF(AB17<=5,"On time","Delayed")) -> Delayed
A18: ORD10017 | B18: C004 | C18: P203 | D18: 22/02/2026 | E18: 46084 | F18: Amit Sharma | G18: Female | H18: 16/01/2002 | I18: Pune | J18: West | K18: Home Appliances | L18: Microwave | M18: 13 | N18: 8500 | O18: 20 | P18: 88400 | Q18: 4 | R18: Card | S18: Rahul | T18: anita.gupta@company.com | U18: 9692599404 | V18: Pending | W18: =IF(OR(Q18<=2,V18="Cancelled"),"Blacklisted",IF(AND(P18>100000,Q18>=4,O18<=10%,V18="Completed"),"Platinum",IF(AND(P18>=50000,Q18>=3,V18="Completed"),"Gold",IF(AND(P18<50000,V18="Completed"),"Silver","")))) | X18: =PROPER(TRIM(F18)) -> Amit Sharma | Y18: =LEFT(F18,3)&MID(B18,2,3)&LEFT(I18,2) -> Ami004Pu | Z18: =IF(ISNUMBER(SEARCH("@",T18)),LOWER(TRIM(T18)),"invalid email") -> anita.gupta@company.com | AA18: =IF(H17="","",IFERROR(DATEDIF(IF(ISNUMBER(H17),H17,DATE(VALUE(RIGHT(H17,4)),VALUE(MID(H17,3,2)),VALUE(LEFT(H17,2)))),TODAY(),"Y"),"")) -> 23 | AB18: =IF(OR(D18="",E18=""),"",IFERROR(DATE(MID(E18,7,4),MID(E18,4,2),LEFT(E18,2))-DATE(MID(D18,7,4),MID(D18,4,2),LEFT(D18,2)),"")) | AC18: =IF(E18="","Pending",IF(AB18<=5,"On time","Delayed")) -> Delayed
A19: ORD10018 | B19: C007 | C19: P203 | D19: 28/02/2026 | E19: 46145 | F19: Arjun Rao | G19: Male | H19: 32761 | I19: Ahmedabad | J19: West | K19: Home Appliances | L19: Microwave | M19: 4 | N19: 8500 | O19: 20 | P19: 27200 | Q19: 5 | R19: Card | S19: Aisha | T19: arjun.rao@company.com | U19: 9426119622 | V19: Pending | W19: =IF(OR(Q19<=2,V19="Cancelled"),"Blacklisted",IF(AND(P19>100000,Q19>=4,O19<=10%,V19="Completed"),"Platinum",IF(AND(P19>=50000,Q19>=3,V19="Completed"),"Gold",IF(AND(P19<50000,V19="Completed"),"Silver","")))) | X19: =PROPER(TRIM(F19)) -> Arjun Rao | Y19: =LEFT(F19,3)&MID(B19,2,3)&LEFT(I19,2) -> Arj007Ah | Z19: =IF(ISNUMBER(SEARCH("@",T19)),LOWER(TRIM(T19)),"invalid email") -> arjun.rao@company.com | AA19: =IF(H18="","",IFERROR(DATEDIF(IF(ISNUMBER(H18),H18,DATE(VALUE(RIGHT(H18,4)),VALUE(MID(H18,3,2)),VALUE(LEFT(H18,2)))),TODAY(),"Y"),"")) | AB19: =IF(OR(D19="",E19=""),"",IFERROR(DATE(MID(E19,7,4),MID(E19,4,2),LEFT(E19,2))-DATE(MID(D19,7,4),MID(D19,4,2),LEFT(D19,2)),"")) | AC19: =IF(E19="","Pending",IF(AB19<=5,"On time","Delayed")) -> Delayed
A20: ORD10019 | B20: C007 | C20: P102 | D20: 45669 | E20: 45759 | F20: arjun rao | G20: Male | H20: 28/10/1991 | I20: Mumbai | J20: West | K20: Electronics | L20: Mouse | M20: 9 | N20: 700 | O20: 5 | P20: 5985 | Q20: 3 | R20: UPI | S20: Ritika | T20: arjun.Rao@company.com | U20: 9184436009 | V20: Pending | W20: =IF(OR(Q20<=2,V20="Cancelled"),"Blacklisted",IF(AND(P20>100000,Q20>=4,O20<=10%,V20="Completed"),"Platinum",IF(AND(P20>=50000,Q20>=3,V20="Completed"),"Gold",IF(AND(P20<50000,V20="Completed"),"Silver","")))) | X20: =PROPER(TRIM(F20)) -> Arjun Rao | Y20: =LEFT(F20,3)&MID(B20,2,3)&LEFT(I20,2) -> arj007Mu | Z20: =IF(ISNUMBER(SEARCH("@",T20)),LOWER(TRIM(T20)),"invalid email") -> arjun.rao@company.com | AA20: =IF(H19="","",IFERROR(DATEDIF(IF(ISNUMBER(H19),H19,DATE(VALUE(RIGHT(H19,4)),VALUE(MID(H19,3,2)),VALUE(LEFT(H19,2)))),TODAY(),"Y"),"")) -> 37 | AB20: =IF(OR(D20="",E20=""),"",IFERROR(DATE(MID(E20,7,4),MID(E20,4,2),LEFT(E20,2))-DATE(MID(D20,7,4),MID(D20,4,2),LEFT(D20,2)),"")) | AC20: =IF(E20="","Pending",IF(AB20<=5,"On time","Delayed")) -> Delayed
A21: ORD10020 | B21: C008 | C21: P101 | D21: 25/06/2025 | E21: 45723 | F21: Kavya Nair | G21: Female | H21: 32876 | I21: Ahmedabad | J21: West | K21: Electronics | L21: Laptop | M21: 8 | N21: 55000 | O21: 20 | P21: 352000 | Q21: 1 | R21: Cash | S21: Karan | T21: kavya.nair@company.com | U21: 9263774934 | V21: Completed | W21: =IF(OR(Q21<=2,V21="Cancelled"),"Blacklisted",IF(AND(P21>100000,Q21>=4,O21<=10%,V21="Completed"),"Platinum",IF(AND(P21>=50000,Q21>=3,V21="Completed"),"Gold",IF(AND(P21<50000,V21="Completed"),"Silver","")))) -> Blacklisted | X21: =PROPER(TRIM(F21)) -> Kavya Nair | Y21: =LEFT(F21,3)&MID(B21,2,3)&LEFT(I21,2) -> Kav008Ah | Z21: =IF(ISNUMBER(SEARCH("@",T21)),LOWER(TRIM(T21)),"invalid email") -> kavya.nair@company.com | AA21: =IF(H20="","",IFERROR(DATEDIF(IF(ISNUMBER(H20),H20,DATE(VALUE(RIGHT(H20,4)),VALUE(MID(H20,3,2)),VALUE(LEFT(H20,2)))),TODAY(),"Y"),"")) | AB21: =IF(OR(D21="",E21=""),"",IFERROR(DATE(MID(E21,7,4),MID(E21,4,2),LEFT(E21,2))-DATE(MID(D21,7,4),MID(D21,4,2),LEFT(D21,2)),"")) | AC21: =IF(E21="","Pending",IF(AB21<=5,"On time","Delayed")) -> Delayed
A22: ORD10021 | B22: C003 | C22: P102 | D22: 26/04/2025 | E22: 45782 | F22: Rohit Singh | G22: Male | H22: 18/07/2002 | I22: Delhi | J22: North | K22: electronics | L22: Mouse | M22: 10 | N22: 700 | O22: 20 | P22: 5600 | Q22: 4 | R22: Card | S22: Aisha | T22: rohit.singh@company.com | U22: 9473159572 | V22: Cancelled | W22: =IF(OR(Q22<=2,V22="Cancelled"),"Blacklisted",IF(AND(P22>100000,Q22>=4,O22<=10%,V22="Completed"),"Platinum",IF(AND(P22>=50000,Q22>=3,V22="Completed"),"Gold",IF(AND(P22<50000,V22="Completed"),"Silver","")))) -> Blacklisted | X22: =PROPER(TRIM(F22)) -> Rohit Singh | Y22: =LEFT(F22,3)&MID(B22,2,3)&LEFT(I22,2) -> Roh003De | Z22: =IF(ISNUMBER(SEARCH("@",T22)),LOWER(TRIM(T22)),"invalid email") -> rohit.singh@company.com | AA22: =IF(H21="","",IFERROR(DATEDIF(IF(ISNUMBER(H21),H21,DATE(VALUE(RIGHT(H21,4)),VALUE(MID(H21,3,2)),VALUE(LEFT(H21,2)))),TODAY(),"Y"),"")) -> 36 | AB22: =IF(OR(D22="",E22=""),"",IFERROR(DATE(MID(E22,7,4),MID(E22,4,2),LEFT(E22,2))-DATE(MID(D22,7,4),MID(D22,4,2),LEFT(D22,2)),"")) | AC22: =IF(E22="","Pending",IF(AB22<=5,"On time","Delayed")) -> Delayed
A23: ORD10022 | B23: C008 | C23: P201 | D23: 45717 | E23: 45870 | F23: kavya Nair | G23: Female | H23: 15/12/2004 | I23: Bengaluru | J23: South | K23: Home Appliances | L23: Mixer | M23: 1 | N23: 3500 | O23: 5 | P23: 3325 | Q23: 3 | R23: UPI | S23: Neha | T23: kavya.nair@company.com | U23: 9660493688 | V23: Cancelled | W23: =IF(OR(Q23<=2,V23="Cancelled"),"Blacklisted",IF(AND(P23>100000,Q23>=4,O23<=10%,V23="Completed"),"Platinum",IF(AND(P23>=50000,Q23>=3,V23="Completed"),"Gold",IF(AND(P23<50000,V23="Completed"),"Silver","")))) -> Blacklisted | X23: =PROPER(TRIM(F23)) -> Kavya Nair | Y23: =LEFT(F23,3)&MID(B23,2,3)&LEFT(I23,2) -> kav008Be | Z23: =IF(ISNUMBER(SEARCH("@",T23)),LOWER(TRIM(T23)),"invalid email") -> kavya.nair@company.com | AA23: =IF(H22="","",IFERROR(DATEDIF(IF(ISNUMBER(H22),H22,DATE(VALUE(RIGHT(H22,4)),VALUE(MID(H22,3,2)),VALUE(LEFT(H22,2)))),TODAY(),"Y"),"")) | AB23: =IF(OR(D23="",E23=""),"",IFERROR(DATE(MID(E23,7,4),MID(E23,4,2),LEFT(E23,2))-DATE(MID(D23,7,4),MID(D23,4,2),LEFT(D23,2)),"")) | AC23: =IF(E23="","Pending",IF(AB23<=5,"On time","Delayed")) -> Delayed
A24: ORD10023 | B24: C002 | C24: P102 | D24: 19/04/2025 | E24: 30/04/2025 | F24: Priya Patel | G24: Female | H24: 30779 | I24: Jaipur | J24: North | K24: Electronics | L24: Mouse | M24: 19 | N24: 700 | O24: 15 | P24: 11305 | Q24: 3 | R24: NetBanking | S24: Karan | T24: priya.patel@company.com | U24: 9513325819 | V24: Pending | W24: =IF(OR(Q24<=2,V24="Cancelled"),"Blacklisted",IF(AND(P24>100000,Q24>=4,O24<=10%,V24="Completed"),"Platinum",IF(AND(P24>=50000,Q24>=3,V24="Completed"),"Gold",IF(AND(P24<50000,V24="Completed"),"Silver","")))) | X24: =PROPER(TRIM(F24)) -> Priya Patel | Y24: =LEFT(F24,3)&MID(B24,2,3)&LEFT(I24,2) -> Pri002Ja | Z24: =IF(ISNUMBER(SEARCH("@",T24)),LOWER(TRIM(T24)),"invalid email") -> priya.patel@company.com | AA24: =IF(H23="","",IFERROR(DATEDIF(IF(ISNUMBER(H23),H23,DATE(VALUE(RIGHT(H23,4)),VALUE(MID(H23,3,2)),VALUE(LEFT(H23,2)))),TODAY(),"Y"),"")) | AB24: =IF(OR(D24="",E24=""),"",IFERROR(DATE(MID(E24,7,4),MID(E24,4,2),LEFT(E24,2))-DATE(MID(D24,7,4),MID(D24,4,2),LEFT(D24,2)),"")) -> 11 | AC24: =IF(E24="","Pending",IF(AB24<=5,"On time","Delayed")) -> Delayed
A25: ORD10024 | B25: C009 | C25: P101 | D25: 22/12/2025 | E25: 46023 | F25: Mohit Verma | G25: Male | H25: 25/02/1978 | I25: Bengaluru | J25: South | K25: Electronics | L25: Laptop | M25: 12 | N25: 55000 | O25: 0 | P25: 660000 | Q25: 1 | R25: Card | S25: Rahul | T25: mohit.verma@company.com | U25: 9641063242 | V25: Pending | W25: =IF(OR(Q25<=2,V25="Cancelled"),"Blacklisted",IF(AND(P25>100000,Q25>=4,O25<=10%,V25="Completed"),"Platinum",IF(AND(P25>=50000,Q25>=3,V25="Completed"),"Gold",IF(AND(P25<50000,V25="Completed"),"Silver","")))) -> Blacklisted | X25: =PROPER(TRIM(F25)) -> Mohit Verma | Y25: =LEFT(F25,3)&MID(B25,2,3)&LEFT(I25,2) -> Moh009Be | Z25: =IF(ISNUMBER(SEARCH("@",T25)),LOWER(TRIM(T25)),"invalid email") -> mohit.verma@company.com | AA25: =IF(H24="","",IFERROR(DATEDIF(IF(ISNUMBER(H24),H24,DATE(VALUE(RIGHT(H24,4)),VALUE(MID(H24,3,2)),VALUE(LEFT(H24,2)))),TODAY(),"Y"),"")) -> 42 | AB25: =IF(OR(D25="",E25=""),"",IFERROR(DATE(MID(E25,7,4),MID(E25,4,2),LEFT(E25,2))-DATE(MID(D25,7,4),MID(D25,4,2),LEFT(D25,2)),"")) | AC25: =IF(E25="","Pending",IF(AB25<=5,"On time","Delayed")) -> Delayed
A26: ORD10025 | B26: C005 | C26: P302 | D26: 46269 | E26: 20/04/2026 | F26: Vikas Mehta | G26: Male | H26: 33305 | I26: Mumbai | J26: West | K26: Stationery | L26: Pen | M26: 1 | N26: 20 | O26: 5 | P26: 19 | Q26: 5 | R26: Card | S26: Ritika | T26: vikas.mehta@company.com | U26: 9277372518 | V26: Cancelled | W26: =IF(OR(Q26<=2,V26="Cancelled"),"Blacklisted",IF(AND(P26>100000,Q26>=4,O26<=10%,V26="Completed"),"Platinum",IF(AND(P26>=50000,Q26>=3,V26="Completed"),"Gold",IF(AND(P26<50000,V26="Completed"),"Silver","")))) -> Blacklisted | X26: =PROPER(TRIM(F26)) -> Vikas Mehta | Y26: =LEFT(F26,3)&MID(B26,2,3)&LEFT(I26,2) -> Vik005Mu | Z26: =IF(ISNUMBER(SEARCH("@",T26)),LOWER(TRIM(T26)),"invalid email") -> vikas.mehta@company.com | AA26: =IF(H25="","",IFERROR(DATEDIF(IF(ISNUMBER(H25),H25,DATE(VALUE(RIGHT(H25,4)),VALUE(MID(H25,3,2)),VALUE(LEFT(H25,2)))),TODAY(),"Y"),"")) | AB26: =IF(OR(D26="",E26=""),"",IFERROR(DATE(MID(E26,7,4),MID(E26,4,2),LEFT(E26,2))-DATE(MID(D26,7,4),MID(D26,4,2),LEFT(D26,2)),"")) | AC26: =IF(E26="","Pending",IF(AB26<=5,"On time","Delayed")) -> Delayed
A27: ORD10026 | B27: C007 | C27: P302 | D27: 24/06/2025 | E27: 45695 | F27: Arjun Rao | G27: Male | H27: 28441 | I27: Mumbai | J27: West | K27: Stationery | L27: Pen | M27: 2 | N27: 20 | O27: 15 | P27: 34 | Q27: 1 | R27: UPI | S27: Ritika | T27: arjun.rao@company.com | U27: 9193154372 | V27: Pending | W27: =IF(OR(Q27<=2,V27="Cancelled"),"Blacklisted",IF(AND(P27>100000,Q27>=4,O27<=10%,V27="Completed"),"Platinum",IF(AND(P27>=50000,Q27>=3,V27="Completed"),"Gold",IF(AND(P27<50000,V27="Completed"),"Silver","")))) -> Blacklisted | X27: =PROPER(TRIM(F27)) -> Arjun Rao | Y27: =LEFT(F27,3)&MID(B27,2,3)&LEFT(I27,2) -> Arj007Mu | Z27: =IF(ISNUMBER(SEARCH("@",T27)),LOWER(TRIM(T27)),"invalid email") -> arjun.rao@company.com | AA27: =IF(H26="","",IFERROR(DATEDIF(IF(ISNUMBER(H26),H26,DATE(VALUE(RIGHT(H26,4)),VALUE(MID(H26,3,2)),VALUE(LEFT(H26,2)))),TODAY(),"Y"),"")) -> 35 | AB27: =IF(OR(D27="",E27=""),"",IFERROR(DATE(MID(E27,7,4),MID(E27,4,2),LEFT(E27,2))-DATE(MID(D27,7,4),MID(D27,4,2),LEFT(D27,2)),"")) | AC27: =IF(E27="","Pending",IF(AB27<=5,"On time","Delayed")) -> Delayed
A28: ORD10027 | B28: C009 | C28: P201 | D28: 22/05/2025 | E28: 25/05/2025 | F28: Mohit Verma | G28: Male | H28: 33818 | I28: Ahmedabad | J28: West | K28: Home Appliances | L28: Mixer | M28: 12 | N28: 3500 | O28: 15 | P28: 35700 | Q28: 4 | R28: Cash | S28: Rahul | T28: mohit.verma@company.com | U28: 9400073244 | V28: Cancelled | W28: =IF(OR(Q28<=2,V28="Cancelled"),"Blacklisted",IF(AND(P28>100000,Q28>=4,O28<=10%,V28="Completed"),"Platinum",IF(AND(P28>=50000,Q28>=3,V28="Completed"),"Gold",IF(AND(P28<50000,V28="Completed"),"Silver","")))) -> Blacklisted | X28: =PROPER(TRIM(F28)) -> Mohit Verma | Y28: =LEFT(F28,3)&MID(B28,2,3)&LEFT(I28,2) -> Moh009Ah | Z28: =IF(ISNUMBER(SEARCH("@",T28)),LOWER(TRIM(T28)),"invalid email") -> mohit.verma@company.com | AA28: =IF(H27="","",IFERROR(DATEDIF(IF(ISNUMBER(H27),H27,DATE(VALUE(RIGHT(H27,4)),VALUE(MID(H27,3,2)),VALUE(LEFT(H27,2)))),TODAY(),"Y"),"")) -> 48 | AB28: =IF(OR(D28="",E28=""),"",IFERROR(DATE(MID(E28,7,4),MID(E28,4,2),LEFT(E28,2))-DATE(MID(D28,7,4),MID(D28,4,2),LEFT(D28,2)),"")) -> 3 | AC28: =IF(E28="","Pending",IF(AB28<=5,"On time","Delayed")) -> On time
A29: ORD10028 | B29: C008 | C29: P103 | D29: 13/03/2026 | E29: 20/03/2026 | F29: Kavya Nair | G29: Female | H29: 38113 | I29: Ahmedabad | J29: West | K29: Electronics | L29: Keyboard | M29: 11 | N29: 1200 | O29: 0 | P29: 13200 | Q29: 2 | R29: UPI | S29: Karan | T29: kavya.nair@company.com | U29: 9771556720 | V29: Completed | W29: =IF(OR(Q29<=2,V29="Cancelled"),"Blacklisted",IF(AND(P29>100000,Q29>=4,O29<=10%,V29="Completed"),"Platinum",IF(AND(P29>=50000,Q29>=3,V29="Completed"),"Gold",IF(AND(P29<50000,V29="Completed"),"Silver","")))) -> Blacklisted | X29: =PROPER(TRIM(F29)) -> Kavya Nair | Y29: =LEFT(F29,3)&MID(B29,2,3)&LEFT(I29,2) -> Kav008Ah | Z29: =IF(ISNUMBER(SEARCH("@",T29)),LOWER(TRIM(T29)),"invalid email") -> kavya.nair@company.com | AA29: =IF(H28="","",IFERROR(DATEDIF(IF(ISNUMBER(H28),H28,DATE(VALUE(RIGHT(H28,4)),VALUE(MID(H28,3,2)),VALUE(LEFT(H28,2)))),TODAY(),"Y"),"")) -> 34 | AB29: =IF(OR(D29="",E29=""),"",IFERROR(DATE(MID(E29,7,4),MID(E29,4,2),LEFT(E29,2))-DATE(MID(D29,7,4),MID(D29,4,2),LEFT(D29,2)),"")) -> 7 | AC29: =IF(E29="","Pending",IF(AB29<=5,"On time","Delayed")) -> Delayed
A30: ORD10029 | B30: C003 | C30: P203 | D30: 45878 | E30: 20/09/2025 | F30: Rohit Singh | G30: Male | H30: 37203 | I30: Pune | J30: West | K30: Home Appliances | L30: Microwave | M30: 6 | N30: 8500 | O30: 65 | P30: 51000 | Q30: 1 | R30: Card | S30: Aisha | T30: rohit.singh@company.com | U30: 9127480734 | V30: Completed | W30: =IF(OR(Q30<=2,V30="Cancelled"),"Blacklisted",IF(AND(P30>100000,Q30>=4,O30<=10%,V30="Completed"),"Platinum",IF(AND(P30>=50000,Q30>=3,V30="Completed"),"Gold",IF(AND(P30<50000,V30="Completed"),"Silver","")))) -> Blacklisted | X30: =PROPER(TRIM(F30)) -> Rohit Singh | Y30: =LEFT(F30,3)&MID(B30,2,3)&LEFT(I30,2) -> Roh003Pu | Z30: =IF(ISNUMBER(SEARCH("@",T30)),LOWER(TRIM(T30)),"invalid email") -> rohit.singh@company.com | AA30: =IF(H29="","",IFERROR(DATEDIF(IF(ISNUMBER(H29),H29,DATE(VALUE(RIGHT(H29,4)),VALUE(MID(H29,3,2)),VALUE(LEFT(H29,2)))),TODAY(),"Y"),"")) -> 22 | AB30: =IF(OR(D30="",E30=""),"",IFERROR(DATE(MID(E30,7,4),MID(E30,4,2),LEFT(E30,2))-DATE(MID(D30,7,4),MID(D30,4,2),LEFT(D30,2)),"")) | AC30: =IF(E30="","Pending",IF(AB30<=5,"On time","Delayed")) -> Delayed
A31: ORD10030 | B31: C006 | C31: P301 | D31: 46327 | E31: 16/01/2026 | F31: Sneha Joshi | G31: Female | H31: 29680 | I31: Pune | J31: West | K31: Stationery | L31: Notebook | M31: 2 | N31: 60 | O31: 5 | P31: 114 | Q31: 3 | R31: Cash | S31: Karan | T31: sneha.joshi@company.com | U31: 9512997042 | V31: Cancelled | W31: =IF(OR(Q31<=2,V31="Cancelled"),"Blacklisted",IF(AND(P31>100000,Q31>=4,O31<=10%,V31="Completed"),"Platinum",IF(AND(P31>=50000,Q31>=3,V31="Completed"),"Gold",IF(AND(P31<50000,V31="Completed"),"Silver","")))) -> Blacklisted | X31: =PROPER(TRIM(F31)) -> Sneha Joshi | Y31: =LEFT(F31,3)&MID(B31,2,3)&LEFT(I31,2) -> Sne006Pu | Z31: =IF(ISNUMBER(SEARCH("@",T31)),LOWER(TRIM(T31)),"invalid email") -> sneha.joshi@company.com | AA31: =IF(H30="","",IFERROR(DATEDIF(IF(ISNUMBER(H30),H30,DATE(VALUE(RIGHT(H30,4)),VALUE(MID(H30,3,2)),VALUE(LEFT(H30,2)))),TODAY(),"Y"),"")) -> 24 | AB31: =IF(OR(D31="",E31=""),"",IFERROR(DATE(MID(E31,7,4),MID(E31,4,2),LEFT(E31,2))-DATE(MID(D31,7,4),MID(D31,4,2),LEFT(D31,2)),"")) | AC31: =IF(E31="","Pending",IF(AB31<=5,"On time","Delayed")) -> Delayed
A32: ORD10031 | B32: C008 | C32: P303 | D32: 16/06/2025 | E32: 26/06/2025 | F32: Kavya Nair | G32: Female | H32: 35102 | I32: Bengaluru | J32: South | K32: Stationery | L32: Marker | M32: 19 | N32: 45 | O32: 20 | P32: 684 | Q32: 4 | R32: NetBanking | S32: Aisha | T32: kavya.nair@company.com | U32: 9372748661 | V32: Cancelled | W32: =IF(OR(Q32<=2,V32="Cancelled"),"Blacklisted",IF(AND(P32>100000,Q32>=4,O32<=10%,V32="Completed"),"Platinum",IF(AND(P32>=50000,Q32>=3,V32="Completed"),"Gold",IF(AND(P32<50000,V32="Completed"),"Silver","")))) -> Blacklisted | X32: =PROPER(TRIM(F32)) -> Kavya Nair | Y32: =LEFT(F32,3)&MID(B32,2,3)&LEFT(I32,2) -> Kav008Be | Z32: =IF(ISNUMBER(SEARCH("@",T32)),LOWER(TRIM(T32)),"invalid email") -> kavya.nair@company.com | AA32: =IF(H31="","",IFERROR(DATEDIF(IF(ISNUMBER(H31),H31,DATE(VALUE(RIGHT(H31,4)),VALUE(MID(H31,3,2)),VALUE(LEFT(H31,2)))),TODAY(),"Y"),"")) -> 45 | AB32: =IF(OR(D32="",E32=""),"",IFERROR(DATE(MID(E32,7,4),MID(E32,4,2),LEFT(E32,2))-DATE(MID(D32,7,4),MID(D32,4,2),LEFT(D32,2)),"")) -> 10 | AC32: =IF(E32="","Pending",IF(AB32<=5,"On time","Delayed")) -> Delayed
A33: ORD10032 | B33: C002 | C33: P104 | D33: 45664 | E33: 13/07/2025 | F33: Priya Patel | G33: Female | H33: 15/11/1976 | I33: Ahmedabad | J33: West | K33: Electronics | L33: Monitor | M33: 11 | N33: 12000 | O33: 0 | P33: 132000 | Q33: 3 | R33: UPI | S33: Ritika | T33: priya.patel@company.com | U33: 9570437805 | V33: Pending | W33: =IF(OR(Q33<=2,V33="Cancelled"),"Blacklisted",IF(AND(P33>100000,Q33>=4,O33<=10%,V33="Completed"),"Platinum",IF(AND(P33>=50000,Q33>=3,V33="Completed"),"Gold",IF(AND(P33<50000,V33="Completed"),"Silver","")))) | X33: =PROPER(TRIM(F33)) -> Priya Patel | Y33: =LEFT(F33,3)&MID(B33,2,3)&LEFT(I33,2) -> Pri002Ah | Z33: =IF(ISNUMBER(SEARCH("@",T33)),LOWER(TRIM(T33)),"invalid email") -> priya.patel@company.com | AA33: =IF(H32="","",IFERROR(DATEDIF(IF(ISNUMBER(H32),H32,DATE(VALUE(RIGHT(H32,4)),VALUE(MID(H32,3,2)),VALUE(LEFT(H32,2)))),TODAY(),"Y"),"")) -> 30 | AB33: =IF(OR(D33="",E33=""),"",IFERROR(DATE(MID(E33,7,4),MID(E33,4,2),LEFT(E33,2))-DATE(MID(D33,7,4),MID(D33,4,2),LEFT(D33,2)),"")) | AC33: =IF(E33="","Pending",IF(AB33<=5,"On time","Delayed")) -> Delayed
A34: ORD10033 | B34: C006 | C34: P202 | D34: 45841 | E34: 15/03/2025 | F34: Sneha Joshi | G34: Female | H34: 28/10/1988 | I34: Bengaluru | J34: South | K34: Home Appliances | L34: Iron | M34: 20 | N34: 2200 | O34: 5 | P34: 41800 | Q34: 1 | R34: Cash | S34: Rahul | T34: sneha.joshi@company.com | U34: 9310669113 | V34: Pending | W34: =IF(OR(Q34<=2,V34="Cancelled"),"Blacklisted",IF(AND(P34>100000,Q34>=4,O34<=10%,V34="Completed"),"Platinum",IF(AND(P34>=50000,Q34>=3,V34="Completed"),"Gold",IF(AND(P34<50000,V34="Completed"),"Silver","")))) -> Blacklisted | X34: =PROPER(TRIM(F34)) -> Sneha Joshi | Y34: =LEFT(F34,3)&MID(B34,2,3)&LEFT(I34,2) -> Sne006Be | Z34: =IF(ISNUMBER(SEARCH("@",T34)),LOWER(TRIM(T34)),"invalid email") -> sneha.joshi@company.com | AA34: =IF(H33="","",IFERROR(DATEDIF(IF(ISNUMBER(H33),H33,DATE(VALUE(RIGHT(H33,4)),VALUE(MID(H33,3,2)),VALUE(LEFT(H33,2)))),TODAY(),"Y"),"")) | AB34: =IF(OR(D34="",E34=""),"",IFERROR(DATE(MID(E34,7,4),MID(E34,4,2),LEFT(E34,2))-DATE(MID(D34,7,4),MID(D34,4,2),LEFT(D34,2)),"")) | AC34: =IF(E34="","Pending",IF(AB34<=5,"On time","Delayed")) -> Delayed
A35: ORD10034 | B35: C007 | C35: P302 | D35: 24/06/2025 | E35: 45754 | F35: Arjun Rao | G35: Male | H35: 23/06/2004 | I35: Ahmedabad | J35: West | K35: Stationery | L35: Pen | M35: 3 | N35: 20 | O35: 0 | P35: 60 | Q35: 2 | R35: Card | S35: Ritika | T35: wrongmail | U35: 9437132894 | V35: Cancelled | W35: =IF(OR(Q35<=2,V35="Cancelled"),"Blacklisted",IF(AND(P35>100000,Q35>=4,O35<=10%,V35="Completed"),"Platinum",IF(AND(P35>=50000,Q35>=3,V35="Completed"),"Gold",IF(AND(P35<50000,V35="Completed"),"Silver","")))) -> Blacklisted | X35: =PROPER(TRIM(F35)) -> Arjun Rao | Y35: =LEFT(F35,3)&MID(B35,2,3)&LEFT(I35,2) -> Arj007Ah | Z35: =IF(ISNUMBER(SEARCH("@",T35)),LOWER(TRIM(T35)),"invalid email") -> invalid email | AA35: =IF(H34="","",IFERROR(DATEDIF(IF(ISNUMBER(H34),H34,DATE(VALUE(RIGHT(H34,4)),VALUE(MID(H34,3,2)),VALUE(LEFT(H34,2)))),TODAY(),"Y"),"")) | AB35: =IF(OR(D35="",E35=""),"",IFERROR(DATE(MID(E35,7,4),MID(E35,4,2),LEFT(E35,2))-DATE(MID(D35,7,4),MID(D35,4,2),LEFT(D35,2)),"")) | AC35: =IF(E35="","Pending",IF(AB35<=5,"On time","Delayed")) -> Delayed
A36: ORD10035 | B36: C003 | C36: P303 | D36: 45910 | E36: 19/10/2025 | F36: Rohit Singh | G36: Male | H36: 22/04/1996 | I36: Pune | J36: West | K36: Stationery | L36: Marker | M36: 18 | N36: 45 | O36: 20 | P36: 648 | Q36: 4 | R36: NetBanking | S36: Ritika | T36: rohit.singh@company.com | U36: 9762437243 | V36: Cancelled | W36: =IF(OR(Q36<=2,V36="Cancelled"),"Blacklisted",IF(AND(P36>100000,Q36>=4,O36<=10%,V36="Completed"),"Platinum",IF(AND(P36>=50000,Q36>=3,V36="Completed"),"Gold",IF(AND(P36<50000,V36="Completed"),"Silver","")))) -> Blacklisted | X36: =PROPER(TRIM(F36)) -> Rohit Singh | Y36: =LEFT(F36,3)&MID(B36,2,3)&LEFT(I36,2) -> Roh003Pu | Z36: =IF(ISNUMBER(SEARCH("@",T36)),LOWER(TRIM(T36)),"invalid email") -> rohit.singh@company.com | AA36: =IF(H35="","",IFERROR(DATEDIF(IF(ISNUMBER(H35),H35,DATE(VALUE(RIGHT(H35,4)),VALUE(MID(H35,3,2)),VALUE(LEFT(H35,2)))),TODAY(),"Y"),"")) | AB36: =IF(OR(D36="",E36=""),"",IFERROR(DATE(MID(E36,7,4),MID(E36,4,2),LEFT(E36,2))-DATE(MID(D36,7,4),MID(D36,4,2),LEFT(D36,2)),"")) | AC36: =IF(E36="","Pending",IF(AB36<=5,"On time","Delayed")) -> Delayed
A37: ORD10036 | B37: C003 | C37: P103 | D37: 19/11/2025 | E37: 26/11/2025 | F37: Rohit Singh | G37: Male | H37: 29043 | I37: Bengaluru | J37: South | K37: Electronics | L37: Keyboard | M37: 4 | N37: 1200 | O37: 20 | P37: 3840 | Q37: 3 | R37: NetBanking | S37: Aisha | T37: rohit.singh@company.com | U37: 9149046970 | V37: Completed | W37: =IF(OR(Q37<=2,V37="Cancelled"),"Blacklisted",IF(AND(P37>100000,Q37>=4,O37<=10%,V37="Completed"),"Platinum",IF(AND(P37>=50000,Q37>=3,V37="Completed"),"Gold",IF(AND(P37<50000,V37="Completed"),"Silver","")))) -> Silver | X37: =PROPER(TRIM(F37)) -> Rohit Singh | Y37: =LEFT(F37,3)&MID(B37,2,3)&LEFT(I37,2) -> Roh003Be | Z37: =IF(ISNUMBER(SEARCH("@",T37)),LOWER(TRIM(T37)),"invalid email") -> rohit.singh@company.com | AA37: =IF(H36="","",IFERROR(DATEDIF(IF(ISNUMBER(H36),H36,DATE(VALUE(RIGHT(H36,4)),VALUE(MID(H36,3,2)),VALUE(LEFT(H36,2)))),TODAY(),"Y"),"")) | AB37: =IF(OR(D37="",E37=""),"",IFERROR(DATE(MID(E37,7,4),MID(E37,4,2),LEFT(E37,2))-DATE(MID(D37,7,4),MID(D37,4,2),LEFT(D37,2)),"")) -> 7 | AC37: =IF(E37="","Pending",IF(AB37<=5,"On time","Delayed")) -> Delayed
A38: ORD10037 | B38: C009 | C38: P101 | D38: 45788 | E38: 14/11/2025 | F38: Mohit Verma | G38: Male | H38: 27/09/1980 | I38: Kolkata | J38: East | K38: Electronics | L38: Laptop | M38: 10 | N38: 55000 | O38: 0 | P38: 550000 | Q38: 1 | R38: UPI | S38: Rahul | T38: mohit.verma@company.com | U38: 9869182901 | V38: Cancelled | W38: =IF(OR(Q38<=2,V38="Cancelled"),"Blacklisted",IF(AND(P38>100000,Q38>=4,O38<=10%,V38="Completed"),"Platinum",IF(AND(P38>=50000,Q38>=3,V38="Completed"),"Gold",IF(AND(P38<50000,V38="Completed"),"Silver","")))) -> Blacklisted | X38: =PROPER(TRIM(F38)) -> Mohit Verma | Y38: =LEFT(F38,3)&MID(B38,2,3)&LEFT(I38,2) -> Moh009Ko | Z38: =IF(ISNUMBER(SEARCH("@",T38)),LOWER(TRIM(T38)),"invalid email") -> mohit.verma@company.com | AA38: =IF(H37="","",IFERROR(DATEDIF(IF(ISNUMBER(H37),H37,DATE(VALUE(RIGHT(H37,4)),VALUE(MID(H37,3,2)),VALUE(LEFT(H37,2)))),TODAY(),"Y"),"")) -> 47 | AB38: =IF(OR(D38="",E38=""),"",IFERROR(DATE(MID(E38,7,4),MID(E38,4,2),LEFT(E38,2))-DATE(MID(D38,7,4),MID(D38,4,2),LEFT(D38,2)),"")) | AC38: =IF(E38="","Pending",IF(AB38<=5,"On time","Delayed")) -> Delayed
A39: ORD10038 | B39: C006 | C39: P201 | D39: 46237 | E39: 20/03/2026 | F39: Sneha Joshi | G39: Female | H39: 21/06/1980 | I39: Delhi | J39: North | K39: Home Appliances | L39: Mixer | M39: 20 | N39: 3500 | O39: 10 | P39: 63000 | Q39: 3 | R39: Card | S39: Rahul | T39: sneha.joshi@company.com | U39: 9283578533 | V39: Cancelled | W39: =IF(OR(Q39<=2,V39="Cancelled"),"Blacklisted",IF(AND(P39>100000,Q39>=4,O39<=10%,V39="Completed"),"Platinum",IF(AND(P39>=50000,Q39>=3,V39="Completed"),"Gold",IF(AND(P39<50000,V39="Completed"),"Silver","")))) -> Blacklisted | X39: =PROPER(TRIM(F39)) -> Sneha Joshi | Y39: =LEFT(F39,3)&MID(B39,2,3)&LEFT(I39,2) -> Sne006De | Z39: =IF(ISNUMBER(SEARCH("@",T39)),LOWER(TRIM(T39)),"invalid email") -> sneha.joshi@company.com | AA39: =IF(H38="","",IFERROR(DATEDIF(IF(ISNUMBER(H38),H38,DATE(VALUE(RIGHT(H38,4)),VALUE(MID(H38,3,2)),VALUE(LEFT(H38,2)))),TODAY(),"Y"),"")) | AB39: =IF(OR(D39="",E39=""),"",IFERROR(DATE(MID(E39,7,4),MID(E39,4,2),LEFT(E39,2))-DATE(MID(D39,7,4),MID(D39,4,2),LEFT(D39,2)),"")) | AC39: =IF(E39="","Pending",IF(AB39<=5,"On time","Delayed")) -> Delayed
A40: ORD10039 | B40: C008 | C40: P302 | D40: 13/02/2025 | E40: 19/02/2025 | F40: Kavya Nair | G40: Female | H40: 17/06/1979 | I40: Pune | J40: West | K40: Stationery | L40: Pen | M40: 5 | N40: 1200 | O40: 0 | P40: 100 | Q40: 1 | R40: Cash | S40: Rahul | T40: kavya.nair@company.com | U40: 9963005771 | V40: Cancelled | W40: =IF(OR(Q40<=2,V40="Cancelled"),"Blacklisted",IF(AND(P40>100000,Q40>=4,O40<=10%,V40="Completed"),"Platinum",IF(AND(P40>=50000,Q40>=3,V40="Completed"),"Gold",IF(AND(P40<50000,V40="Completed"),"Silver","")))) -> Blacklisted | X40: =PROPER(TRIM(F40)) -> Kavya Nair | Y40: =LEFT(F40,3)&MID(B40,2,3)&LEFT(I40,2) -> Kav008Pu | Z40: =IF(ISNUMBER(SEARCH("@",T40)),LOWER(TRIM(T40)),"invalid email") -> kavya.nair@company.com | AA40: =IF(H39="","",IFERROR(DATEDIF(IF(ISNUMBER(H39),H39,DATE(VALUE(RIGHT(H39,4)),VALUE(MID(H39,3,2)),VALUE(LEFT(H39,2)))),TODAY(),"Y"),"")) | AB40: =IF(OR(D40="",E40=""),"",IFERROR(DATE(MID(E40,7,4),MID(E40,4,2),LEFT(E40,2))-DATE(MID(D40,7,4),MID(D40,4,2),LEFT(D40,2)),"")) -> 6 | AC40: =IF(E40="","Pending",IF(AB40<=5,"On time","Delayed")) -> Delayed
...

Sheet Sales SSummary Report
A1: Sales SummaryReport
A3: Quesstion | B3: Result
A4: Electronics Completed Orders Total Sales | B4: =SUMIFS(Sheet2!S:S,Sheet2!N:N,"Electronics",Sheet2!Y:Y,"Completed") -> 7222090
A5: Neha North Region Total Sales | B5: =SUMIFS(Sheet2!S:S,Sheet2!V:V,"Neha",Sheet2!M:M,"North") -> 1550369.2
A6: Orders With Discount>=15%and UPI | B6: =COUNTIFS(Sheet2!R:R,">=15%",Sheet2!U:U,"UPI") -> 83
A7: Customerss With Rating 5and Completed Orders | B7: =COUNTIFS(Sheet2!T:T,5,Sheet2!Y:Y,"Completed") -> 27
A8: Average Sales in West Region with Quantity>5 | B8: =AVERAGEIFS(Sheet2!S:S,Sheet2!M:M,"West",Sheet2!P:P,">5") -> 82824.451
C12: 0

Sheet Sales Statistics Report
A1: Sales Statistics Report
A3: Statistic | B3: Result
A4: Average Sales | B4: =AVERAGE(Sheet1!P:P) -> 69531.875
A5: Median Sales | B5: =MEDIAN(Sheet1!P:P) -> 10475
A6: Highest Sales | B6: =MAX(Sheet1!P:P) -> 1045000
A7: Lowest Sales | B7: =MIN(Sheet1!P:P) -> 19
A8: Standard Deviation | B8: =_xlfn.STDEV.S(Sheet1!P:P) -> 167151.45
A9: 90th Percentile | B9: =_xlfn.PERCENTILE.INC(Sheet1!P:P,0.9) -> 163880
A10: 90th percentile Meaaning | B10: 90% of Sales Values are less than or equal to this value.

Sheet Financial Analysis Report
A1: Financial Analysis Report
A3: Metrics | B3: Result
A4: Future Value of Monthly Investment | B4: =ROUND(FV(0.1/12,60,-50000,0,0),2) -> 3871853.6
A5: Monthly Investment Required | B5: =ROUND(PMT(10%/12,60,0,-5000000),2) -> 64568.56
A6: Monthly EMI For Equipment Loan | B6: =ROUND(PMT(9%/12,60,1000000)*-1,0) -> 20758

Sheet Product Performance Report
A1: Product Performance Report
A3: Metric | B3: Result
A4: Total Revenue(Quantity*Unit Price) | B4: =SUMPRODUCT(Sheet2!P2:P10000,Sheet2!Q2:Q10000) -> 36610875
A5: Weighted Average Unit Price | B5: =SUMPRODUCT(Sheet2!P2:P10000,Sheet2!Q2:Q10000)/SUM(Sheet2!P2:P10000) -> 6990.8106
A6: Difference Between Calculated Revenue and Sales | B6: =SUMPRODUCT(Sheet2!P2:P10000,Sheet2!Q2:Q10000)-SUM(Sheet2!S2:S10000) -> 1844937.5
A7: Total Discounted Amount | B7: {=SUMPRODUCT(Sheet2!P2:P10000,Sheet2!Q2:Q10000,Sheet2!R2:R10000/100)} -> 2918151.5

Sheet Cleaned_Data
A1: Order ID | B1: Customer_ID | C1: Product_ID | D1: Order_Date | E1: Delivery_Date | F1: Customer_Name | G1: Gender | H1: DOB | I1: City | J1: Region | K1: Category | L1: Product_Name | M1: Quantity | N1: Unit_Price | O1: Discount_% | P1: Sales | Q1: Rating | R1: Payment_Mode | S1: Salesperson | T1: Email | U1: Phone | V1: Order_Status | W1: Customer Classification | X1: Standarized Customer Name | Y1: Customer Code | Z1: Standerized Email | AA1: Customer age | AB1: Delivery Time | AC1: DELIVERY status | AK1: month-year
A2: ORD10001 | B2: C008 | C2: P202 | D2: 18/09/2025 | E2: 22/09/2025 | F2: Kavya Nair | G2: Female | H2: 27767 | I2: Hyderabad | J2: South | K2: Home Appliances | L2: Iron | M2: 4 | N2: 2200 | O2: 10 | P2: 7920 | Q2: 4 | R2: Cash | S2: Ritika | T2: KAvya.nair@company.com | U2: 9431429797 | V2: Completed | W2: =IF(OR(Q2<=2,V2="Cancelled"),"Blacklisted",IF(AND(P2>100000,Q2>=4,O2<=10%,V2="Completed"),"Platinum",IF(AND(P2>=50000,Q2>=3,V2="Completed"),"Gold",IF(AND(P2<50000,V2="Completed"),"Silver","")))) -> Silver | X2: =PROPER(TRIM(F2)) -> Kavya Nair | Y2: =LEFT(F2,3)&MID(B2,2,3)&LEFT(I2,2) -> Kav008Hy | Z2: =IF(ISNUMBER(SEARCH("@",T2)),LOWER(TRIM(T2)),"invalid email") -> kavya.nair@company.com | AA2: =DATEDIF(H2,TODAY(),"Y") -> 50 | AB2: =IF(OR(D2="",E2=""),"",IFERROR(DATE(MID(E2,7,4),MID(E2,4,2),LEFT(E2,2))-DATE(MID(D2,7,4),MID(D2,4,2),LEFT(D2,2)),"")) -> 4 | AC2: =IF(E2="","Pending",IF(AB2<=5,"On time","Delayed")) -> On time | AD2: =IF(TRIM(S2)="","Not Assigned",S2) -> Ritika | AE2: =PROPER(TRIM(F2)) -> Kavya Nair | AF2: =PROPER(TRIM(K2)) -> Home Appliances | AG2: =PROPER(TRIM(J2)) -> South | AH2: =PROPER(TRIM(K2)) -> Home Appliances | AI2: =IF(OR(LOWER(TRIM(K2))="electronic",LOWER(TRIM(K2))="electronics"),"Electronics",PROPER(TRIM(K2))) -> Home Appliances | AK2: =IF(COUNTIF($A$2:A2,A2)=1,1,0) -> 1
A3: ORD10001 | B3: C008 | C3: P104 | D3: 27/04/2025 | E3: 45752 | F3: Kavya Nair | G3: Female | H3: 16/10/2000 | I3: Delhi | J3: North | K3: Electronics | L3: Monitor | M3: 17 | N3: 12000 | O3: 10 | P3: 183600 | Q3: 1 | R3: NetBanking | S3: Rahul | T3: kavya.nair@company.com | U3: 9129865339 | V3: Completed | W3: =IF(OR(Q3<=2,V3="Cancelled"),"Blacklisted",IF(AND(P3>100000,Q3>=4,O3<=10%,V3="Completed"),"Platinum",IF(AND(P3>=50000,Q3>=3,V3="Completed"),"Gold",IF(AND(P3<50000,V3="Completed"),"Silver","")))) -> Blacklisted | X3: =PROPER(TRIM(F3)) -> Kavya Nair | Y3: =LEFT(F3,3)&MID(B3,2,3)&LEFT(I3,2) -> Kav008De | Z3: =IF(ISNUMBER(SEARCH("@",T3)),LOWER(TRIM(T3)),"invalid email") -> kavya.nair@company.com | AA3: =IF(H2="","",IFERROR(DATEDIF(IF(ISNUMBER(H2),H2,DATE(VALUE(RIGHT(H2,4)),VALUE(MID(H2,3,2)),VALUE(LEFT(H2,2)))),TODAY(),"Y"),"")) -> 50 | AB3: =IF(OR(D3="",E3=""),"",IFERROR(DATE(MID(E3,7,4),MID(E3,4,2),LEFT(E3,2))-DATE(MID(D3,7,4),MID(D3,4,2),LEFT(D3,2)),"")) | AC3: =IF(E3="","Pending",IF(AB3<=5,"On time","Delayed")) -> Delayed | AD3: =IF(TRIM(S3)="","Not Assigned",S3) -> Rahul | AE3: =PROPER(TRIM(F3)) -> Kavya Nair | AF3: =PROPER(TRIM(K3)) -> Electronics | AG3: =PROPER(TRIM(J3)) -> North | AH3: =PROPER(TRIM(K3)) -> Electronics | AI3: =IF(OR(LOWER(TRIM(K3))="electronic",LOWER(TRIM(K3))="electronics"),"Electronics",PROPER(TRIM(K3))) -> Electronics | AK3: =IF(COUNTIF($A$2:A3,A3)=1,1,0) -> 0
A4: ORD10006 | B4: C007 | C4: P202 | D4: 46113 | E4: 46357 | F4: Arjun Rao | G4: Male | H4: 32326 | I4: Hyderabad | J4: South | K4: Home Appliances | L4: Iron | M4: 4 | N4: 2200 | O4: 0 | P4: 8800 | Q4: 1 | R4: UPI | S4: Ritika | T4: arjun.rao@company.com | U4: 9780584905 | V4: Completed | W4: =IF(OR(Q4<=2,V4="Cancelled"),"Blacklisted",IF(AND(P4>100000,Q4>=4,O4<=10%,V4="Completed"),"Platinum",IF(AND(P4>=50000,Q4>=3,V4="Completed"),"Gold",IF(AND(P4<50000,V4="Completed"),"Silver","")))) -> Blacklisted | X4: =PROPER(TRIM(F4)) -> Arjun Rao | Y4: =LEFT(F4,3)&MID(B4,2,3)&LEFT(I4,2) -> Arj007Hy | Z4: =IF(ISNUMBER(SEARCH("@",T4)),LOWER(TRIM(T4)),"invalid email") -> arjun.rao@company.com | AA4: =IF(H3="","",IFERROR(DATEDIF(IF(ISNUMBER(H3),H3,DATE(VALUE(RIGHT(H3,4)),VALUE(MID(H3,3,2)),VALUE(LEFT(H3,2)))),TODAY(),"Y"),"")) | AB4: =IF(OR(D4="",E4=""),"",IFERROR(DATE(MID(E4,7,4),MID(E4,4,2),LEFT(E4,2))-DATE(MID(D4,7,4),MID(D4,4,2),LEFT(D4,2)),"")) | AC4: =IF(E4="","Pending",IF(AB4<=5,"On time","Delayed")) -> Delayed | AD4: =IF(TRIM(S4)="","Not Assigned",S4) -> Ritika | AE4: =PROPER(TRIM(F4)) -> Arjun Rao | AF4: =PROPER(TRIM(K4)) -> Home Appliances | AG4: =PROPER(TRIM(J4)) -> South | AH4: =PROPER(TRIM(K4)) -> Home Appliances | AI4: =IF(OR(LOWER(TRIM(K4))="electronic",LOWER(TRIM(K4))="electronics"),"Electronics",PROPER(TRIM(K4))) -> Home Appliances | AK4: =IF(COUNTIF($A$2:A4,A4)=1,1,0) -> 1
A5: ORD10007 | B5: C008 | C5: P201 | D5: 31/02/2025 | E5: 25/02/2026 | F5: Kavya Nair | G5: Female | H5: 20/03/2003 | I5: Hyderabad | J5: South | K5: Home Appliances | L5: Mixer | M5: 2 | N5: 3500 | O5: 5 | P5: 6650 | Q5: 1 | R5: UPI | S5: Ritika | T5: kavya.nair@company.com | U5: 9958252176 | V5: Completed | W5: =IF(OR(Q5<=2,V5="Cancelled"),"Blacklisted",IF(AND(P5>100000,Q5>=4,O5<=10%,V5="Completed"),"Platinum",IF(AND(P5>=50000,Q5>=3,V5="Completed"),"Gold",IF(AND(P5<50000,V5="Completed"),"Silver","")))) -> Blacklisted | X5: =PROPER(TRIM(F5)) -> Kavya Nair | Y5: =LEFT(F5,3)&MID(B5,2,3)&LEFT(I5,2) -> Kav008Hy | Z5: =IF(ISNUMBER(SEARCH("@",T5)),LOWER(TRIM(T5)),"invalid email") -> kavya.nair@company.com | AA5: =IF(H4="","",IFERROR(DATEDIF(IF(ISNUMBER(H4),H4,DATE(VALUE(RIGHT(H4,4)),VALUE(MID(H4,3,2)),VALUE(LEFT(H4,2)))),TODAY(),"Y"),"")) -> 38 | AB5: =IF(OR(D5="",E5=""),"",IFERROR(DATE(MID(E5,7,4),MID(E5,4,2),LEFT(E5,2))-DATE(MID(D5,7,4),MID(D5,4,2),LEFT(D5,2)),"")) -> 359 | AC5: =IF(E5="","Pending",IF(AB5<=5,"On time","Delayed")) -> Delayed | AD5: =IF(TRIM(S5)="","Not Assigned",S5) -> Ritika | AE5: =PROPER(TRIM(F5)) -> Kavya Nair | AF5: =PROPER(TRIM(K5)) -> Home Appliances | AG5: =PROPER(TRIM(J5)) -> South | AH5: =PROPER(TRIM(K5)) -> Home Appliances | AI5: =IF(OR(LOWER(TRIM(K5))="electronic",LOWER(TRIM(K5))="electronics"),"Electronics",PROPER(TRIM(K5))) -> Home Appliances | AK5: =IF(COUNTIF($A$2:A5,A5)=1,1,0) -> 1
A6: ORD10008 | B6: C002 | C6: P104 | D6: 13/04/2025 | E6: 19/04/2025 | F6: Priya Patel | G6: Female | H6: 34883 | I6: Mumbai | J6: West | K6: Electronics | L6: Monitor | M6: 14 | N6: 12000 | O6: 15 | P6: 142800 | Q6: 4 | R6: NetBanking | S6: Ritika | T6: priYa.patel@company.com | U6: 9705521654 | V6: Completed | W6: =IF(OR(Q6<=2,V6="Cancelled"),"Blacklisted",IF(AND(P6>100000,Q6>=4,O6<=10%,V6="Completed"),"Platinum",IF(AND(P6>=50000,Q6>=3,V6="Completed"),"Gold",IF(AND(P6<50000,V6="Completed"),"Silver","")))) -> Gold | X6: =PROPER(TRIM(F6)) -> Priya Patel | Y6: =LEFT(F6,3)&MID(B6,2,3)&LEFT(I6,2) -> Pri002Mu | Z6: =IF(ISNUMBER(SEARCH("@",T6)),LOWER(TRIM(T6)),"invalid email") -> priya.patel@company.com | AA6: =IF(H5="","",IFERROR(DATEDIF(IF(ISNUMBER(H5),H5,DATE(VALUE(RIGHT(H5,4)),VALUE(MID(H5,3,2)),VALUE(LEFT(H5,2)))),TODAY(),"Y"),"")) | AB6: =IF(OR(D6="",E6=""),"",IFERROR(DATE(MID(E6,7,4),MID(E6,4,2),LEFT(E6,2))-DATE(MID(D6,7,4),MID(D6,4,2),LEFT(D6,2)),"")) -> 6 | AC6: =IF(E6="","Pending",IF(AB6<=5,"On time","Delayed")) -> Delayed | AD6: =IF(TRIM(S6)="","Not Assigned",S6) -> Ritika | AE6: =PROPER(TRIM(F6)) -> Priya Patel | AF6: =PROPER(TRIM(K6)) -> Electronics | AG6: =PROPER(TRIM(J6)) -> West | AH6: =PROPER(TRIM(K6)) -> Electronics | AI6: =IF(OR(LOWER(TRIM(K6))="electronic",LOWER(TRIM(K6))="electronics"),"Electronics",PROPER(TRIM(K6))) -> Electronics | AK6: =IF(COUNTIF($A$2:A6,A6)=1,1,0) -> 1
A7: ORD10009 | B7: C008 | C7: P104 | D7: 31/01/2026 | E7: 46055 | F7: Kavya Nair | G7: Female | H7: 35585 | I7: Pune | J7: West | K7: Electronics | L7: Monitor | M7: 4 | N7: 12000 | O7: 15 | P7: 40800 | Q7: 4 | R7: UPI | S7: Neha | T7: kavya.nair@company.com | U7: 9588041011 | V7: Completed | W7: =IF(OR(Q7<=2,V7="Cancelled"),"Blacklisted",IF(AND(P7>100000,Q7>=4,O7<=10%,V7="Completed"),"Platinum",IF(AND(P7>=50000,Q7>=3,V7="Completed"),"Gold",IF(AND(P7<50000,V7="Completed"),"Silver","")))) -> Silver | X7: =PROPER(TRIM(F7)) -> Kavya Nair | Y7: =LEFT(F7,3)&MID(B7,2,3)&LEFT(I7,2) -> Kav008Pu | Z7: =IF(ISNUMBER(SEARCH("@",T7)),LOWER(TRIM(T7)),"invalid email") -> kavya.nair@company.com | AA7: =IF(H6="","",IFERROR(DATEDIF(IF(ISNUMBER(H6),H6,DATE(VALUE(RIGHT(H6,4)),VALUE(MID(H6,3,2)),VALUE(LEFT(H6,2)))),TODAY(),"Y"),"")) -> 31 | AB7: =IF(OR(D7="",E7=""),"",IFERROR(DATE(MID(E7,7,4),MID(E7,4,2),LEFT(E7,2))-DATE(MID(D7,7,4),MID(D7,4,2),LEFT(D7,2)),"")) | AC7: =IF(E7="","Pending",IF(AB7<=5,"On time","Delayed")) -> Delayed | AD7: =IF(TRIM(S7)="","Not Assigned",S7) -> Neha | AE7: =PROPER(TRIM(F7)) -> Kavya Nair | AF7: =PROPER(TRIM(K7)) -> Electronics | AG7: =PROPER(TRIM(J7)) -> West | AH7: =PROPER(TRIM(K7)) -> Electronics | AI7: =IF(OR(LOWER(TRIM(K7))="electronic",LOWER(TRIM(K7))="electronics"),"Electronics",PROPER(TRIM(K7))) -> Electronics | AK7: =IF(COUNTIF($A$2:A7,A7)=1,1,0) -> 1
A8: ORD10010 | B8: C002 | C8: P301 | D8: 25/03/2025 | E8: 27/03/2025 | F8: Priya Patel | G8: Female | H8: 33055 | I8: Mumbai | J8: West | K8: Stationery | L8: Notebook | M8: 6 | N8: 60 | O8: 0 | P8: 360 | Q8: 4 | R8: Card | S8: Neha | T8: PRiya.patel@company.com | U8: 9340540608 | V8: Completed | W8: =IF(OR(Q8<=2,V8="Cancelled"),"Blacklisted",IF(AND(P8>100000,Q8>=4,O8<=10%,V8="Completed"),"Platinum",IF(AND(P8>=50000,Q8>=3,V8="Completed"),"Gold",IF(AND(P8<50000,V8="Completed"),"Silver","")))) -> Silver | X8: =PROPER(TRIM(F8)) -> Priya Patel | Y8: =LEFT(F8,3)&MID(B8,2,3)&LEFT(I8,2) -> Pri002Mu | Z8: =IF(ISNUMBER(SEARCH("@",T8)),LOWER(TRIM(T8)),"invalid email") -> priya.patel@company.com | AA8: =IF(H7="","",IFERROR(DATEDIF(IF(ISNUMBER(H7),H7,DATE(VALUE(RIGHT(H7,4)),VALUE(MID(H7,3,2)),VALUE(LEFT(H7,2)))),TODAY(),"Y"),"")) -> 29 | AB8: =IF(OR(D8="",E8=""),"",IFERROR(DATE(MID(E8,7,4),MID(E8,4,2),LEFT(E8,2))-DATE(MID(D8,7,4),MID(D8,4,2),LEFT(D8,2)),"")) -> 2 | AC8: =IF(E8="","Pending",IF(AB8<=5,"On time","Delayed")) -> On time | AD8: =IF(TRIM(S8)="","Not Assigned",S8) -> Neha | AE8: =PROPER(TRIM(F8)) -> Priya Patel | AF8: =PROPER(TRIM(K8)) -> Stationery | AG8: =PROPER(TRIM(J8)) -> West | AH8: =PROPER(TRIM(K8)) -> Stationery | AI8: =IF(OR(LOWER(TRIM(K8))="electronic",LOWER(TRIM(K8))="electronics"),"Electronics",PROPER(TRIM(K8))) -> Stationery | AK8: =IF(COUNTIF($A$2:A8,A8)=1,1,0) -> 1
A9: ORD10011 | B9: C003 | C9: P202 | D9: 19/09/2025 | E9: 23/09/2025 | F9: Rohit Singh | G9: Male | H9: 30229 | I9: Delhi | J9: North | K9: Home Appliances | L9: Iron | M9: -3 | N9: 2200 | O9: 0 | P9: 35200 | Q9: 2 | R9: Card | S9: Rahul | T9: rohit.singh@company.com | U9: 9521710321 | V9: Pending | W9: =IF(OR(Q9<=2,V9="Cancelled"),"Blacklisted",IF(AND(P9>100000,Q9>=4,O9<=10%,V9="Completed"),"Platinum",IF(AND(P9>=50000,Q9>=3,V9="Completed"),"Gold",IF(AND(P9<50000,V9="Completed"),"Silver","")))) -> Blacklisted | X9: =PROPER(TRIM(F9)) -> Rohit Singh | Y9: =LEFT(F9,3)&MID(B9,2,3)&LEFT(I9,2) -> Roh003De | Z9: =IF(ISNUMBER(SEARCH("@",T9)),LOWER(TRIM(T9)),"invalid email") -> rohit.singh@company.com | AA9: =IF(H8="","",IFERROR(DATEDIF(IF(ISNUMBER(H8),H8,DATE(VALUE(RIGHT(H8,4)),VALUE(MID(H8,3,2)),VALUE(LEFT(H8,2)))),TODAY(),"Y"),"")) -> 36 | AB9: =IF(OR(D9="",E9=""),"",IFERROR(DATE(MID(E9,7,4),MID(E9,4,2),LEFT(E9,2))-DATE(MID(D9,7,4),MID(D9,4,2),LEFT(D9,2)),"")) -> 4 | AC9: =IF(E9="","Pending",IF(AB9<=5,"On time","Delayed")) -> On time | AD9: =IF(TRIM(S9)="","Not Assigned",S9) -> Rahul | AE9: =PROPER(TRIM(F9)) -> Rohit Singh | AF9: =PROPER(TRIM(K9)) -> Home Appliances | AG9: =PROPER(TRIM(J9)) -> North | AH9: =PROPER(TRIM(K9)) -> Home Appliances | AI9: =IF(OR(LOWER(TRIM(K9))="electronic",LOWER(TRIM(K9))="electronics"),"Electronics",PROPER(TRIM(K9))) -> Home Appliances | AK9: =IF(COUNTIF($A$2:A9,A9)=1,1,0) -> 1
A10: ORD10012 | B10: C008 | C10: P201 | D10: 45872 | E10: 15/03/2025 | F10: Kavya Nair | G10: Female | H10: 23/01/1982 | I10: Ahmedabad | J10: West | K10: Home Appliances | L10: Mixer | M10: 10 | N10: 3500 | O10: 5 | P10: 33250 | Q10: 5 | R10: Card | S10: Aisha | T10: kavya.nair@company.com | U10: 9123535241 | V10: Cancelled | W10: =IF(OR(Q10<=2,V10="Cancelled"),"Blacklisted",IF(AND(P10>100000,Q10>=4,O10<=10%,V10="Completed"),"Platinum",IF(AND(P10>=50000,Q10>=3,V10="Completed"),"Gold",IF(AND(P10<50000,V10="Completed"),"Silver","")))) -> Blacklisted | X10: =PROPER(TRIM(F10)) -> Kavya Nair | Y10: =LEFT(F10,3)&MID(B10,2,3)&LEFT(I10,2) -> Kav008Ah | Z10: =IF(ISNUMBER(SEARCH("@",T10)),LOWER(TRIM(T10)),"invalid email") -> kavya.nair@company.com | AA10: =IF(H9="","",IFERROR(DATEDIF(IF(ISNUMBER(H9),H9,DATE(VALUE(RIGHT(H9,4)),VALUE(MID(H9,3,2)),VALUE(LEFT(H9,2)))),TODAY(),"Y"),"")) -> 44 | AB10: =IF(OR(D10="",E10=""),"",IFERROR(DATE(MID(E10,7,4),MID(E10,4,2),LEFT(E10,2))-DATE(MID(D10,7,4),MID(D10,4,2),LEFT(D10,2)),"")) | AC10: =IF(E10="","Pending",IF(AB10<=5,"On time","Delayed")) -> Delayed | AD10: =IF(TRIM(S10)="","Not Assigned",S10) -> Aisha | AE10: =PROPER(TRIM(F10)) -> Kavya Nair | AF10: =PROPER(TRIM(K10)) -> Home Appliances | AG10: =PROPER(TRIM(J10)) -> West | AH10: =PROPER(TRIM(K10)) -> Home Appliances | AI10: =IF(OR(LOWER(TRIM(K10))="electronic",LOWER(TRIM(K10))="electronics"),"Electronics",PROPER(TRIM(K10))) -> Home Appliances | AK10: =IF(COUNTIF($A$2:A10,A10)=1,1,0) -> 1
